Workbook
Name NativeTimeline_Fecha: #N/A
Name SegmentaciónDeDatos_Categoría: #N/A
Name SegmentaciónDeDatos_Categoría1: #N/A
Name SegmentaciónDeDatos_Provincia: #N/A
Name SegmentaciónDeDatos_Vendedor: #N/A
Name SegmentaciónDeDatos_Vendedor1: #N/A

Sheet BaseDeDatos
B2: Documento | C2: Fecha | D2: Id Cliente | E2: Cliente | F2: Ciudad | G2: Provincia | H2: Vendedor | I2: Empresa | J2: Forma de pago | K2: Producto | L2: Categoría | M2: Precio | N2: Cantidad | O2: Ventas
B3: 1 | C3: 43930 | D3: 9259377217 | E3: Empresa AA | F3: Cuenca | G3: Azuay | H3: Mayra Aguilar Sepúlveda | I3: Empresa de embarque B | J3: Cheque | K3: Cerveza | L3: Bebidas | M3: 14 | N3: 10 | O3: =BaseDeDatos!$M3*BaseDeDatos!$N3 -> 140
B4: 2 | C4: 44068 | D4: 6185253419 | E4: Empresa AA | F4: Cuenca | G4: Azuay | H4: Mayra Aguilar Sepúlveda | I4: Empresa de embarque B | J4: Cheque | K4: Ciruelas secas | L4: Frutas secas | M4: 34 | N4: 1 | O4: =BaseDeDatos!$M4*BaseDeDatos!$N4 -> 34
B5: 3 | C5: 43908 | D5: 2308885942 | E5: Empresa D | F5: Azogues | G5: Canar | H5: Andrés González Rico | I5: Empresa de embarque A | J5: Tarjeta de crédito | K5: Peras secas | L5: Frutas secas | M5: 14 | N5: 57 | O5: =BaseDeDatos!$M5*BaseDeDatos!$N5 -> 798
B6: 4 | C6: 43974 | D6: 6199717898 | E6: Empresa D | F6: Azogues | G6: Canar | H6: Andrés González Rico | I6: Empresa de embarque A | J6: Tarjeta de crédito | K6: Manzanas secas | L6: Frutas secas | M6: 16 | N6: 72 | O6: =BaseDeDatos!$M6*BaseDeDatos!$N6 -> 1152
B7: 5 | C7: 43944 | D7: 5540683029 | E7: Empresa D | F7: Azogues | G7: Canar | H7: Andrés González Rico | I7: Empresa de embarque A | J7: Tarjeta de crédito | K7: Ciruelas secas | L7: Frutas secas | M7: 12 | N7: 68 | O7: =BaseDeDatos!$M7*BaseDeDatos!$N7 -> 816
B8: 6 | C8: 44184 | D8: 6343955045 | E8: Empresa L | F8: Cuenca | G8: Azuay | H8: Mayra Aguilar Sepúlveda | I8: Empresa de embarque B | J8: Tarjeta de crédito | K8: Té chai | L8: Bebidas | M8: 22 | N8: 29 | O8: =BaseDeDatos!$M8*BaseDeDatos!$N8 -> 638
B9: 7 | C9: 44133 | D9: 1572125717 | E9: Empresa L | F9: Cuenca | G9: Azuay | H9: Mayra Aguilar Sepúlveda | I9: Empresa de embarque B | J9: Tarjeta de crédito | K9: Café | L9: Bebidas | M9: 42 | N9: 41 | O9: =BaseDeDatos!$M9*BaseDeDatos!$N9 -> 1722
B10: 8 | C10: 43863 | D10: 3776895536 | E10: Empresa H | F10: Riobamba | G10: Chimborazo | H10: Nancy Gil de la Peña | I10: Empresa de embarque C | J10: Tarjeta de crédito | K10: Galletas de chocolate | L10: Productos horneados | M10: 11 | N10: 18 | O10: =BaseDeDatos!$M10*BaseDeDatos!$N10 -> 198
B11: 9 | C11: 44158 | D11: 390733860 | E11: Empresa D | F11: Azogues | G11: Canar | H11: Andrés González Rico | I11: Empresa de embarque C | J11: Cheque | K11: Galletas de chocolate | L11: Productos horneados | M11: 29 | N11: 73 | O11: =BaseDeDatos!$M11*BaseDeDatos!$N11 -> 2117
B12: 10 | C12: 43863 | D12: 2456709195 | E12: Empresa CC | F12: Guayaquil | G12: Guayas | H12: José de Jesús Morales | I12: Empresa de embarque B | J12: Cheque | K12: Chocolate | L12: Dulces | M12: 12 | N12: 79 | O12: =BaseDeDatos!$M12*BaseDeDatos!$N12 -> 948
B13: 11 | C13: 43999 | D13: 5766090086 | E13: Empresa C | F13: Machala | G13: El Oro | H13: Mayra Aguilar Sepúlveda | I13: Empresa de embarque B | J13: Efectivo | K13: Almejas | L13: Sopas | M13: 28 | N13: 37 | O13: =BaseDeDatos!$M13*BaseDeDatos!$N13 -> 1036
B14: 12 | C14: 44045 | D14: 4872781256 | E14: Empresa F | F14: Ibarra | G14: Imbabura | H14: Luis Miguel Valdés Garza | I14: Empresa de embarque B | J14: Tarjeta de crédito | K14: Salsa curry | L14: Salsas | M14: 33 | N14: 64 | O14: =BaseDeDatos!$M14*BaseDeDatos!$N14 -> 2112
... B17: 15 | C17: 44037 | D17: 8539365209 | E17: Empresa J | F17: Esmeraldas | G17: Esmeraldas | H17: Laura Gutiérrez Saenz | I17: Empresa de embarque B | J17: Tarjeta de crédito | K17: Té verde | L17: Bebidas | M17: 41 | N17: 96 | O17: =BaseDeDatos!$M17*BaseDeDatos!$N17 -> 3936
B18: 16 | C18: 44009 | D18: 6983099686 | E18: Empresa G | F18: Guaranda | G18: Guaranda | H18: Nancy Gil de la Peña | K18: Café | L18: Bebidas | M18: 45 | N18: 97 | O18: =BaseDeDatos!$M18*BaseDeDatos!$N18 -> 4365
B19: 17 | C19: 44065 | D19: 3008945605 | E19: Empresa J | F19: Esmeraldas | G19: Esmeraldas | H19: Laura Gutiérrez Saenz | I19: Empresa de embarque A | K19: Jalea de fresa | L19: Mermeladas y jaleas | M19: 26 | N19: 65 | O19: =BaseDeDatos!$M19*BaseDeDatos!$N19 -> 1690
B20: 18 | C20: 43937 | D20: 5388305959 | E20: Empresa J | F20: Esmeraldas | G20: Esmeraldas | H20: Laura Gutiérrez Saenz | I20: Empresa de embarque A | K20: Condimento cajún | L20: Condimentos | M20: 40 | N20: 88 | O20: =BaseDeDatos!$M20*BaseDeDatos!$N20 -> 3520
B21: 19 | C21: 44172 | D21: 438272084 | E21: Empresa J | F21: Esmeraldas | G21: Esmeraldas | H21: Laura Gutiérrez Saenz | I21: Empresa de embarque A | K21: Galletas de chocolate | L21: Productos horneados | M21: 12 | N21: 60 | O21: =BaseDeDatos!$M21*BaseDeDatos!$N21 -> 720
B22: 20 | C22: 43875 | D22: 2536792311 | E22: Empresa K | F22: Quito | G22: Pichincha | H22: Ana del Valle Hinojosa | I22: Empresa de embarque C | K22: Ciruelas secas | L22: Frutas secas | M22: 35 | N22: 96 | O22: =BaseDeDatos!$M22*BaseDeDatos!$N22 -> 3360
B23: 21 | C23: 44138 | D23: 7813757711 | E23: Empresa K | F23: Quito | G23: Pichincha | H23: Ana del Valle Hinojosa | I23: Empresa de embarque C | K23: Té verde | L23: Bebidas | M23: 20 | N23: 50 | O23: =BaseDeDatos!$M23*BaseDeDatos!$N23 -> 1000
B24: 22 | C24: 43918 | D24: 4786931679 | E24: Empresa A | F24: Ambato | G24: Tungurahua | H24: Nancy Gil de la Peña | K24: Té chai | L24: Bebidas | M24: 50 | N24: 75 | O24: =BaseDeDatos!$M24*BaseDeDatos!$N24 -> 3750
B25: 23 | C25: 44039 | D25: 3021659728 | E25: Empresa A | F25: Ambato | G25: Tungurahua | H25: Nancy Gil de la Peña | K25: Café | L25: Bebidas | M25: 21 | N25: 4 | O25: =BaseDeDatos!$M25*BaseDeDatos!$N25 -> 84
B26: 24 | C26: 43993 | D26: 2591950684 | E26: Empresa A | F26: Ambato | G26: Tungurahua | H26: Nancy Gil de la Peña | K26: Té verde | L26: Bebidas | M26: 43 | N26: 18 | O26: =BaseDeDatos!$M26*BaseDeDatos!$N26 -> 774
B27: 25 | C27: 43885 | D27: 9326361454 | E27: Empresa BB | F27: Manta | G27: Manabi | H27: Ana del Valle Hinojosa | I27: Empresa de embarque C | J27: Tarjeta de crédito | K27: Almejas | L27: Sopas | M27: 26 | N27: 49 | O27: =BaseDeDatos!$M27*BaseDeDatos!$N27 -> 1274
B28: 26 | C28: 44055 | D28: 3769138349 | E28: Empresa BB | F28: Manta | G28: Manabi | H28: Ana del Valle Hinojosa | I28: Empresa de embarque C | J28: Tarjeta de crédito | K28: Carne de cangrejo | L28: Carne enlatada | M28: 39 | N28: 21 | O28: =BaseDeDatos!$M28*BaseDeDatos!$N28 -> 819
B29: 27 | C29: 43908 | D29: 5871657714 | E29: Empresa I | F29: Guayaquil | G29: Guayas | H29: Robert Zárate Carrillo | I29: Empresa de embarque A | J29: Cheque | K29: Ravioli | L29: Pasta | M29: 33 | N29: 8 | O29: =BaseDeDatos!$M29*BaseDeDatos!$N29 -> 264
B30: 28 | C30: 43965 | D30: 1534553307 | E30: Empresa I | F30: Guayaquil | G30: Guayas | H30: Robert Zárate Carrillo | I30: Empresa de embarque A | J30: Cheque | K30: Mozzarella | L30: Productos lácteos | M30: 46 | N30: 82 | O30: =BaseDeDatos!$M30*BaseDeDatos!$N30 -> 3772
B31: 29 | C31: 44146 | D31: 8474620707 | E31: Empresa F | F31: Ibarra | G31: Imbabura | H31: Luis Miguel Valdés Garza | I31: Empresa de embarque B | J31: Tarjeta de crédito | K31: Cerveza | L31: Bebidas | M31: 32 | N31: 75 | O31: =BaseDeDatos!$M31*BaseDeDatos!$N31 -> 2400
B32: 30 | C32: 44144 | D32: 3530767380 | E32: Empresa H | F32: Riobamba | G32: Chimborazo | H32: Nancy Gil de la Peña | I32: Empresa de embarque B | J32: Cheque | K32: Salsa curry | L32: Salsas | M32: 34 | N32: 3 | O32: =BaseDeDatos!$M32*BaseDeDatos!$N32 -> 102
B33: 31 | C33: 43845 | D33: 6673950624 | E33: Empresa C | F33: Machala | G33: El Oro | H33: Mayra Aguilar Sepúlveda | I33: Empresa de embarque B | J33: Efectivo | K33: Jarabe | L33: Condimentos | M33: 24 | N33: 33 | O33: =BaseDeDatos!$M33*BaseDeDatos!$N33 -> 792
B34: 32 | C34: 43967 | D34: 7137547321 | E34: Empresa C | F34: Machala | G34: El Oro | H34: Mayra Aguilar Sepúlveda | I34: Empresa de embarque B | J34: Efectivo | K34: Salsa curry | L34: Salsas | M34: 21 | N34: 51 | O34: =BaseDeDatos!$M34*BaseDeDatos!$N34 -> 1071
B35: 33 | C35: 43862 | D35: 9655985375 | E35: Empresa F | F35: Ibarra | G35: Imbabura | H35: Luis Miguel Valdés Garza | I35: Empresa de embarque B | J35: Tarjeta de crédito | L35: Tarifa de envío
B36: 34 | C36: 44167 | D36: 299812367 | E36: Empresa BB | F36: Manta | G36: Manabi | H36: Ana del Valle Hinojosa | I36: Empresa de embarque C | J36: Cheque | L36: Tarifa de envío
B37: 35 | C37: 43870 | D37: 7779151222 | E37: Empresa H | F37: Riobamba | G37: Chimborazo | H37: Nancy Gil de la Peña | I37: Empresa de embarque C | J37: Cheque | L37: Tarifa de envío
B38: 36 | C38: 44192 | D38: 9282360094 | E38: Empresa J | F38: Esmeraldas | G38: Esmeraldas | H38: Laura Gutiérrez Saenz | I38: Empresa de embarque B | J38: Tarjeta de crédito | K38: Almendras | L38: Frutas secas | M38: 140 | N38: 47 | O38: =BaseDeDatos!$M38*BaseDeDatos!$N38 -> 6580
B39: 37 | C39: 43982 | D39: 6935804403 | E39: Empresa J | F39: Esmeraldas | G39: Esmeraldas | H39: Laura Gutiérrez Saenz | I39: Empresa de embarque A | K39: Ciruelas secas | L39: Frutas secas | M39: 49 | N39: 49 | O39: =BaseDeDatos!$M39*BaseDeDatos!$N39 -> 2401
B40: 38 | C40: 43952 | D40: 3650322132 | E40: Empresa K | F40: Quito | G40: Pichincha | H40: Ana del Valle Hinojosa | I40: Empresa de embarque C | K40: Salsa curry | L40: Salsas | M40: 560 | N40: 72 | O40: =BaseDeDatos!$M40*BaseDeDatos!$N40 -> 40320
B41: 39 | C41: 43965 | D41: 1985754250 | E41: Empresa A | F41: Ambato | G41: Tungurahua | H41: Nancy Gil de la Peña | I41: Empresa de embarque C | K41: Carne de cangrejo | L41: Carne enlatada | M41: 257.6 | N41: 13 | O41: =BaseDeDatos!$M41*BaseDeDatos!$N41 -> 3348.8
B42: 40 | C42: 44090 | D42: 7293507918 | E42: Empresa BB | F42: Manta | G42: Manabi | H42: Ana del Valle Hinojosa | I42: Empresa de embarque C | J42: Tarjeta de crédito | K42: Café | L42: Bebidas | M42: 644 | N42: 32 | O42: =BaseDeDatos!$M42*BaseDeDatos!$N42 -> 20608
B43: 41 | C43: 43983 | D43: 3459323228 | E43: Empresa I | F43: Guayaquil | G43: Guayas | H43: Robert Zárate Carrillo | I43: Empresa de embarque A | J43: Cheque | K43: Almejas | L43: Sopas | M43: 135.1 | N43: 27 | O43: =BaseDeDatos!$M43*BaseDeDatos!$N43 -> 3647.7
...

Sheet grf
A1: Etiquetas de fila | B1: Suma de Ventas
A2: feb | B2: 65408
A3: Total general | B3: 65408
A16: Etiquetas de fila | B16: Cuenta de Ventas
A17: José de Jesús Morales | B17: 2
A18: Luis Miguel Valdés Garza | B18: 1
A19: Nancy Gil de la Peña | B19: 1
A20: Total general | B20: 4
A27: Etiquetas de fila | B27: Suma de Ventas
A28: Bebidas | B28: 65408
A29: Total general | B29: 65408
A45: Etiquetas de fila | B45: Suma de Ventas
A46: 0-20000 | B46: 25480
A47: 20000-40000 | B47: 39928
A48: Total general | B48: 65408
A59: Etiquetas de fila | B59: Suma de Ventas | D59: provincias | E59: ventas
A60: Guaranda | B60: 39928 | D60: Azuay | E60: =B60 -> 39928
A61: Guayas | B61: 12348 | D61: Canar | E61: =B61 -> 12348
A62: Imbabura | B62: 13132 | D62: Chimborazo | E62: =B62 -> 13132
A63: Total general | B63: 65408 | D63: El Oro | E63: =B63 -> 65408
D64: Esmeraldas | E64: =B64 -> 0
D65: Guaranda | E65: =B65 -> 0
D66: Guayas | E66: =B66 -> 0
D67: Imbabura | E67: =B67 -> 0
D68: Manabi | E68: =B68 -> 0
D69: Pichincha | E69: =B69 -> 0
D70: Tungurahua | E70: =B70 -> 0

Sheet dash
H1: TABLERO DE CONTROL
G2: CONTROL DE VENTAS

Sheet Graficos
A1: Etiquetas de fila | B1: Suma de Ventas
A2: feb | B2: 150262.9
A3: Total general | B3: 150262.9
A16: Etiquetas de fila | B16: Suma de Ventas
A17: José de Jesús Morales | B17: 21685.5
A18: Laura Gutiérrez Saenz | B18: 39894.4
A19: Luis Miguel Valdés Garza | B19: 25004
A20: Nancy Gil de la Peña | B20: 39928
A21: Robert Zárate Carrillo | B21: 23751
A22: Total general | B22: 150262.9
A28: Etiquetas de fila | B28: Suma de Ventas
A29: Bebidas | B29: 65408
A30: Condimentos | B30: 24640
A31: Dulces | B31: 9337.5
A32: Frutas secas | B32: 25452
A33: Pasta | B33: 23751
A34: Productos horneados | B34: 1674.4
A35: Tarifa de envío
A36: Total general | B36: 150262.9
A46: Etiquetas de fila | B46: Suma de Ventas
A47: <0 o (en blanco)
A48: 0-20000 | B48: 61943.9
A49: 20000-40000 | B49: 88319
A50: Total general | B50: 150262.9
A58: Etiquetas de fila | B58: Suma de Ventas | D58: Provincias | E58: Ventas
A59: Esmeraldas | B59: 39894.4 | D59: Azuay | E59: =GETPIVOTDATA("Ventas",$A$58,"Provincia","Azuay") -> #REF!
A60: Guaranda | B60: 39928 | D60: Canar | E60: =GETPIVOTDATA("Ventas",$A$58,"Provincia","Canar") -> #REF!
A61: Guayas | B61: 45436.5 | D61: Chimborazo | E61: =GETPIVOTDATA("Ventas",$A$58,"Provincia","Chimborazo") -> #REF!
A62: Imbabura | B62: 25004 | D62: El Oro | E62: =GETPIVOTDATA("Ventas",$A$58,"Provincia","El Oro") -> #REF!
A63: Total general | B63: 150262.9 | D63: Esmeraldas | E63: =GETPIVOTDATA("Ventas",$A$58,"Provincia","Esmeraldas") -> 39894.4
D64: Guaranda | E64: =GETPIVOTDATA("Ventas",$A$58,"Provincia","Guaranda") -> 39928
D65: Guayas | E65: =GETPIVOTDATA("Ventas",$A$58,"Provincia","Guayas") -> 45436.5
D66: Imbabura | E66: =GETPIVOTDATA("Ventas",$A$58,"Provincia","Imbabura") -> 25004
D67: Manabi | E67: =GETPIVOTDATA("Ventas",$A$58,"Provincia","Manabi") -> #REF!
D68: Pichincha | E68: =GETPIVOTDATA("Ventas",$A$58,"Provincia","Pichincha") -> #REF!
D69: Tungurahua | E69: =GETPIVOTDATA("Ventas",$A$58,"Provincia","Tungurahua") -> #REF!

Sheet DashBoard
H1: TABLERO DE CONTROL
H3: Control de Ventas
